Workbook

Sheet RPA RoadMap (2)
A1: Sr# | B1: UseCase Name | C1: Average Transactions (Annual) | D1: OCR / NON-OCR | E1: Already in production | F1: Automation Required | G1: RPA Complexity | H1: Estimated Efforts(Weeks) | I1: Developer | J1: Timeline
A2: 1 | B2: Data Change – Override Manager | C2: 6089 | D2: NON-OCR | E2: Y | F2: Y | G2: Medium | I2: Varun
A3: 2 | B3: Data Change – Use Position Reports To | C3: 3933 | D3: NON-OCR | E3: Y | F3: Y | G3: Simple | I3: Varun
A4: 3 | B4: Job Architecture | C4: 10692 | D4: NON-OCR | E4: Y | F4: Y | G4: Medium | I4: Varun
A5: 4 | B5: Job Description Update | C5: 7168 | D5: NON-OCR | E5: N | F5: Y | G5: Complex | H5: =VLOOKUP(_xlfn.CONCAT(D5,G5),'Estimation Guidelines'!C:L,10,FALSE) -> 8.6 | I5: Kishor | J5: Mar-April
A6: 5 | B6: Data Change – Override Person Job Band | C6: 4 | D6: NON-OCR | F6: N
A7: 6 | B7: Data Change – Use Position Job Band | C7: 7 | D7: NON-OCR | F7: N
A8: 7 | B8: Data Change – Data Change | C8: 6804 | D8: NON-OCR | E8: N | F8: Y | G8: Medium | H8: =VLOOKUP(_xlfn.CONCAT(D8,G8),'Estimation Guidelines'!C:L,10,FALSE) -> 5.8 | I8: Kishor | J8: May
A9: 8 | B9: External Hire Poornata ID creation | C9: 5170 | D9: NON-OCR | E9: N | F9: Y | G9: Complex | H9: =VLOOKUP(_xlfn.CONCAT(D9,G9),'Estimation Guidelines'!C:L,10,FALSE) -> 8.6 | I9: Kishor | J9: June- July
A10: 9 | B10: Poornata ID creation (Add a Person - Smart HR) | C10: 1057 | D10: NON-OCR | F10: N | G10: Medium
A11: 10 | B11: Poornata ID Creation (Add a Person) - Excel Template | C11: 5159 | D11: NON-OCR | E11: N | F11: Y | G11: Complex | H11: =VLOOKUP(_xlfn.CONCAT(D11,G11),'Estimation Guidelines'!C:L,10,FALSE) -> 8.6 | I11: Kishor | J11: Aug-Sep
A12: 11 | B12: Poornata ID Creation (Add POI/CWR) | C12: 573 | D12: NON-OCR | F12: N | G12: Complex
A13: 12 | B13: Job Data Update (Confirmation/Confirmation with pay rate change/Mobility) | C13: 10119 | D13: OCR | E13: N | F13: Y | G13: Complex | H13: =VLOOKUP(_xlfn.CONCAT(D13,G13),'Estimation Guidelines'!C:L,10,FALSE) -> 11.6 | I13: Rutuja , Vibhav | J13: Nov-Dec-Jan-Feb
A14: 13 | B14: Personal Data Update (Excluding Bulk volume-43,274) | C14: 14504 | D14: OCR | E14: N | F14: Y | G14: Complex | H14: =VLOOKUP(_xlfn.CONCAT(D14,G14),'Estimation Guidelines'!C:L,10,FALSE) -> 11.6 | I14: Rutuja , Vibhav | J14: Nov-Dec-Jan-Feb
A15: 14 | B15: Compensation Update (Excluding bulk volume-71,968) | C15: 7232 | D15: OCR | E15: N | F15: Y | G15: Complex | H15: =VLOOKUP(_xlfn.CONCAT(D15,G15),'Estimation Guidelines'!C:L,10,FALSE) -> 11.6 | I15: Rutuja , Vibhav | J15: Nov-Dec-Jan-Feb
A16: 15 | B16: Creation of Potential Assessment Document | C16: 5337 | D16: NON-OCR | E16: N | F16: Y | G16: Complex | H16: =VLOOKUP(_xlfn.CONCAT(D16,G16),'Estimation Guidelines'!C:L,10,FALSE) -> 8.6 | I16: Kishor | J16: Oct-Nov 2024
A17: 16 | B17: Poornata ID Creation (Add a Person) (Proposed Process Change) | C17: 8925 | D17: OCR | E17: N | F17: Y | G17: Complex | H17: =VLOOKUP(_xlfn.CONCAT(D17,G17),'Estimation Guidelines'!C:L,10,FALSE) -> 11.6 | I17: Rutuja , Vibhav | J17: Aug-Sep-Oct
A18: 17 | B18: Bank Data Update | C18: 3695 | D18: OCR | E18: N | F18: Y | G18: Medium | H18: =VLOOKUP(_xlfn.CONCAT(D18,G18),'Estimation Guidelines'!C:L,10,FALSE) -> 8.8 | I18: Rutuja , Vibhav | J18: April - May-June-July
A19: 18 | B19: Poornata ID creation (Through External Hire) – QC action and update if missing data-Proposed process change | C19: 5854 | D19: OCR | E19: N | F19: Y | G19: Complex | H19: =VLOOKUP(_xlfn.CONCAT(D19,G19),'Estimation Guidelines'!C:L,10,FALSE) -> 11.6 | I19: Rutuja , Vibhav | J19: Aug-Sep-Oct
A20: 19 | B20: Education Data | C20: 2981 | D20: OCR | E20: N | F20: Y | G20: Complex | H20: =VLOOKUP(_xlfn.CONCAT(D20,G20),'Estimation Guidelines'!C:L,10,FALSE) -> 11.6 | I20: Rutuja , Vibhav | J20: April - May-June-July
A21: 20 | B21: National ID, PAN, Aadhar, Passport, Visa, Address | C21: 9845 | D21: OCR | E21: N | F21: Y | G21: Complex | H21: =VLOOKUP(_xlfn.CONCAT(D21,G21),'Estimation Guidelines'!C:L,10,FALSE) -> 11.6 | I21: Rutuja , Vibhav | J21: April - May-June-July
A22: 21 | B22: Learning Session creation | C22: 1277 | D22: NON-OCR | F22: N
A23: 22 | B23: Leave Balance upload | C23: 4243 | D23: NON-OCR | E23: N | F23: Y | G23: Complex | H23: =VLOOKUP(_xlfn.CONCAT(D23,G23),'Estimation Guidelines'!C:L,10,FALSE) -> 8.6 | I23: Kishor | J23: Dec-Jan
A24: 23 | B24: BGV initiation and Report upload Initiate – 20 mins Report upload 10 mins | C24: 5228 | D24: NON-OCR | E24: N | F24: Y | G24: Complex | H24: =VLOOKUP(_xlfn.CONCAT(D24,G24),'Estimation Guidelines'!C:L,10,FALSE) -> 8.6 | I24: Kishor | J24: Feb-Mar 2025
A25: 24 | B25: FnF Settlement | C25: 12829 | D25: NON-OCR | E25: N | F25: Y | G25: Complex | H25: =VLOOKUP(_xlfn.CONCAT(D25,G25),'Estimation Guidelines'!C:L,10,FALSE) -> 8.6 | I25: Ganesh / Tushar | J25: April - May
A26: 25 | B26: Maker-Checker - ACR Letter | D26: NON-OCR | E26: N | F26: Y | G26: Complex | H26: =VLOOKUP(_xlfn.CONCAT(D26,G26),'Estimation Guidelines'!C:L,10,FALSE) -> 8.6 | I26: Ganesh / Tushar | J26: June- July -Aug
A27: 26 | B27: Ticket Creater | C27: 48701 | D27: NON-OCR | E27: Y | F27: Y | G27: Complex | I27: Varun
A28: 27 | B28: Talent Profile Creation BOT | C28: 5310 | D28: NON-OCR | E28: Y | F28: Y | G28: Complex | I28: Varun
A29: 28 | B29: Poornata Status update - SR Update in Transaction | C29: 53182 | D29: NON-OCR | E29: Y | F29: Y | G29: Simple | I29: Viji
A30: 29 | B30: Audit Sampling | D30: NON-OCR | E30: Y | F30: Y | G30: Simple | I30: Viji
A31: 30 | B31: Create a Dashboard | D31: NON-OCR | E31: Y | F31: Y | G31: Simple | I31: Viji
A32: 31 | B32: Cement ticket creator | D32: NON-OCR | E32: Y | F32: Y | G32: Complex | I32: Viji
A33: 32 | B33: Potential Assesment | C33: 6316 | D33: NON-OCR | E33: Y | F33: Y | G33: Medium | I33: Viji
A34: 33 | B34: PH Link Initiation (ABCAP) | C34: 111114 | D34: OCR | E34: N | F34: Y | G34: Complex | H34: =VLOOKUP(_xlfn.CONCAT(D34,G34),'Estimation Guidelines'!C:L,10,FALSE) -> 11.6 | I34: Rutuja , Vibhav | J34: Aug-Sep-Oct
A35: 34 | B35: Cancelling of performance document | C35: 1639 | D35: NON-OCR | E35: N | F35: Y | G35: Medium | H35: =VLOOKUP(_xlfn.CONCAT(D35,G35),'Estimation Guidelines'!C:L,10,FALSE) -> 5.8 | I35: Kishor | J35: April-May 2025
A36: 35 | B36: Creation and Assigning of Curriculum/ Deeplinks/ Online Courses/ Uploading Videos | C36: 2025 | D36: NON-OCR | E36: N | F36: Y | G36: Medium | H36: =VLOOKUP(_xlfn.CONCAT(D36,G36),'Estimation Guidelines'!C:L,10,FALSE) -> 5.8 | I36: Kishor | J36: June-July 2025
A37: 36 | B37: Creation of performance document | C37: 2013 | D37: NON-OCR | E37: N | F37: Y | G37: Complex | H37: =VLOOKUP(_xlfn.CONCAT(D37,G37),'Estimation Guidelines'!C:L,10,FALSE) -> 8.6 | I37: Kishor | J37: Aug-Sep 2025
A38: 37 | B38: Exit_Approval reassignment for Clearance | C38: 1931 | D38: NON-OCR | E38: N | F38: Y | G38: Complex | H38: =VLOOKUP(_xlfn.CONCAT(D38,G38),'Estimation Guidelines'!C:L,10,FALSE) -> 8.6 | I38: Kishor | J38: Oct-Nov 2025
A39: 38 | B39: Holiday Schedule upload | C39: 10287 | D39: NON-OCR | E39: N | F39: Y | G39: Simple | H39: =VLOOKUP(_xlfn.CONCAT(D39,G39),'Estimation Guidelines'!C:L,10,FALSE) -> 4.8 | I39: Kishor | J39: 45992
A40: 39 | B40: Incident Class. / Data / sync issue | C40: 1926 | D40: NON-OCR | E40: N | F40: Y | G40: Medium | H40: =VLOOKUP(_xlfn.CONCAT(D40,G40),'Estimation Guidelines'!C:L,10,FALSE) -> 5.8 | I40: Kishor | J40: Jan - Feb 2026
...

Sheet RPA RoadMap (3)
B1: RPA Use Cases | L1: 2024 | U1: 2025 | AG1: 2026
A2: Sr# | B2: UseCase Name | C2: Average Transactions (Annual) | D2: OCR / NON-OCR | E2: Already in production | F2: Automation Required | G2: RPA Complexity | H2: Estimated Efforts(Weeks) | I2: Developer | J2: Timeline | K2: Smonth | L2: Apr | M2: May | N2: Jun | O2: Jul | P2: Aug | Q2: Sep | R2: Oct | S2: Nov | T2: Dec | U2: Jan | V2: Feb | W2: Mar | X2: Apr | Y2: May | Z2: Jun | AA2: Jul | AB2: Aug | AC2: Sep | AD2: Oct | AE2: Nov | AF2: Dec | AG2: Jan | AH2: Feb | AI2: Mar | AJ2: Apr | AK2: May
A3: 4 | B3: Job Description Update | C3: 7168 | D3: NON-OCR | E3: N | F3: Y | G3: Complex | H3: =VLOOKUP(_xlfn.CONCAT(D3,G3),'Estimation Guidelines'!C:L,10,FALSE) -> 8.6 | I3: Kishor | J3: Mar-April | K3: 202403 | L3: 1
A4: 20 | B4: National ID, PAN, Aadhar, Passport, Visa, Address | C4: 9845 | D4: OCR | E4: N | F4: Y | G4: Complex | H4: =VLOOKUP(_xlfn.CONCAT(D4,G4),'Estimation Guidelines'!C:L,10,FALSE) -> 11.6 | I4: Rutuja , Vibhav | J4: April - May-June-July | K4: 202404 | L4: 1 | M4: 1 | N4: 1 | O4: 1
A5: 17 | B5: Bank Data Update | C5: 3695 | D5: OCR | E5: N | F5: Y | G5: Medium | H5: =VLOOKUP(_xlfn.CONCAT(D5,G5),'Estimation Guidelines'!C:L,10,FALSE) -> 8.8 | I5: Rutuja , Vibhav | J5: April - May-June-July | K5: 202404 | L5: 1 | M5: 1 | N5: 1 | O5: 1
A6: 19 | B6: Education Data | C6: 2981 | D6: OCR | E6: N | F6: Y | G6: Complex | H6: =VLOOKUP(_xlfn.CONCAT(D6,G6),'Estimation Guidelines'!C:L,10,FALSE) -> 11.6 | I6: Rutuja , Vibhav | J6: April - May-June-July | K6: 202404 | L6: 1 | M6: 1 | N6: 1 | O6: 1
A7: 24 | B7: FnF Settlement | C7: 12829 | D7: NON-OCR | E7: N | F7: Y | G7: Complex | H7: =VLOOKUP(_xlfn.CONCAT(D7,G7),'Estimation Guidelines'!C:L,10,FALSE) -> 8.6 | I7: Ganesh / Tushar | J7: April - May | K7: 202404 | L7: 1 | M7: 1
A8: 38 | B8: Holiday Schedule upload | C8: 10287 | D8: NON-OCR | E8: N | F8: Y | G8: Simple | H8: =VLOOKUP(_xlfn.CONCAT(D8,G8),'Estimation Guidelines'!C:L,10,FALSE) -> 4.8 | I8: Kishor | J8: May | K8: 202405 | M8: 1
A9: 41 | B9: Job Data Update | C9: 45835 | D9: NON-OCR | E9: N | F9: Y | G9: Medium | H9: =VLOOKUP(_xlfn.CONCAT(D9,G9),'Estimation Guidelines'!C:L,10,FALSE) -> 5.8 | I9: Kishor | J9: June- July | K9: 202406 | N9: 1 | O9: 1
A10: 25 | B10: Maker-Checker - ACR Letter | D10: NON-OCR | E10: N | F10: Y | G10: Complex | H10: =VLOOKUP(_xlfn.CONCAT(D10,G10),'Estimation Guidelines'!C:L,10,FALSE) -> 8.6 | I10: Ganesh / Tushar | J10: June- July -Aug | K10: 202406 | N10: 1 | O10: 1 | P10: 1
A11: 33 | B11: PH Link Initiation (ABCAP) | C11: 111114 | D11: OCR | E11: N | F11: Y | G11: Complex | H11: =VLOOKUP(_xlfn.CONCAT(D11,G11),'Estimation Guidelines'!C:L,10,FALSE) -> 11.6 | I11: Rutuja , Vibhav | J11: Aug-Sep-Oct | K11: 202408 | P11: 1 | Q11: 1 | R11: 1
A12: 16 | B12: Poornata ID Creation (Add a Person) (Proposed Process Change) | C12: 8925 | D12: OCR | E12: N | F12: Y | G12: Complex | H12: =VLOOKUP(_xlfn.CONCAT(D12,G12),'Estimation Guidelines'!C:L,10,FALSE) -> 11.6 | I12: Rutuja , Vibhav | J12: Aug-Sep-Oct | K12: 202408 | P12: 1 | Q12: 1 | R12: 1
A13: 18 | B13: Poornata ID creation (Through External Hire) – QC action and update if missing data-Proposed process change | C13: 5854 | D13: OCR | E13: N | F13: Y | G13: Complex | H13: =VLOOKUP(_xlfn.CONCAT(D13,G13),'Estimation Guidelines'!C:L,10,FALSE) -> 11.6 | I13: Rutuja , Vibhav | J13: Aug-Sep-Oct | K13: 202408 | P13: 1 | Q13: 1 | R13: 1
A14: 46 | B14: Position Creation/ Updation/ Deactivation and JD Linkage (Job Arch ???) | C14: 9247 | D14: NON-OCR | E14: N | F14: Y | G14: Medium | H14: =VLOOKUP(_xlfn.CONCAT(D14,G14),'Estimation Guidelines'!C:L,10,FALSE) -> 5.8 | I14: Kishor | J14: Aug-Sep | K14: 202408 | P14: 1 | Q14: 1
A15: 15 | B15: Creation of Potential Assessment Document | C15: 5337 | D15: NON-OCR | E15: N | F15: Y | G15: Complex | H15: =VLOOKUP(_xlfn.CONCAT(D15,G15),'Estimation Guidelines'!C:L,10,FALSE) -> 8.6 | I15: Kishor | J15: Oct-Nov 2024 | K15: 202410 | R15: 1 | S15: 1
A16: 13 | B16: Personal Data Update (Excluding Bulk volume-43,274) | C16: 14504 | D16: OCR | E16: N | F16: Y | G16: Complex | H16: =VLOOKUP(_xlfn.CONCAT(D16,G16),'Estimation Guidelines'!C:L,10,FALSE) -> 11.6 | I16: Rutuja , Vibhav | J16: Nov-Dec-Jan-Feb | K16: 202411 | S16: 1 | T16: 1 | U16: 1
A17: 12 | B17: Job Data Update (Confirmation/Confirmation with pay rate change/Mobility) | C17: 10119 | D17: OCR | E17: N | F17: Y | G17: Complex | H17: =VLOOKUP(_xlfn.CONCAT(D17,G17),'Estimation Guidelines'!C:L,10,FALSE) -> 11.6 | I17: Rutuja , Vibhav | J17: Nov-Dec-Jan-Feb | K17: 202411 | S17: 1 | T17: 1 | U17: 1
A18: 14 | B18: Compensation Update (Excluding bulk volume-71,968) | C18: 7232 | D18: OCR | E18: N | F18: Y | G18: Complex | H18: =VLOOKUP(_xlfn.CONCAT(D18,G18),'Estimation Guidelines'!C:L,10,FALSE) -> 11.6 | I18: Rutuja , Vibhav | J18: Nov-Dec-Jan-Feb | K18: 202411 | S18: 1 | T18: 1 | U18: 1
A19: 22 | B19: Leave Balance upload | C19: 4243 | D19: NON-OCR | E19: N | F19: Y | G19: Complex | H19: =VLOOKUP(_xlfn.CONCAT(D19,G19),'Estimation Guidelines'!C:L,10,FALSE) -> 8.6 | I19: Kishor | J19: Dec-Jan | K19: 202412 | T19: 1 | U19: 1
A20: 23 | B20: BGV initiation and Report upload Initiate – 20 mins Report upload 10 mins | C20: 5228 | D20: NON-OCR | E20: N | F20: Y | G20: Complex | H20: =VLOOKUP(_xlfn.CONCAT(D20,G20),'Estimation Guidelines'!C:L,10,FALSE) -> 8.6 | I20: Rutuja | J20: Feb-Mar 2025 | K20: 202502 | V20: 1 | W20: 1
A21: 34 | B21: Cancelling of performance document | C21: 1639 | D21: NON-OCR | E21: N | F21: Y | G21: Medium | H21: =VLOOKUP(_xlfn.CONCAT(D21,G21),'Estimation Guidelines'!C:L,10,FALSE) -> 5.8 | I21: Kishor | J21: Feb-Mar 2025 | K21: 202502 | V21: 1 | W21: 1
A22: 35 | B22: Creation and Assigning of Curriculum/ Deeplinks/ Online Courses/ Uploading Videos | C22: 2025 | D22: NON-OCR | E22: N | F22: Y | G22: Medium | H22: =VLOOKUP(_xlfn.CONCAT(D22,G22),'Estimation Guidelines'!C:L,10,FALSE) -> 5.8 | I22: Rutuja | J22: Apr-May-25 | K22: 202504 | X22: 1 | Y22: 1
A23: 36 | B23: Creation of performance document | C23: 2013 | D23: NON-OCR | E23: N | F23: Y | G23: Complex | H23: =VLOOKUP(_xlfn.CONCAT(D23,G23),'Estimation Guidelines'!C:L,10,FALSE) -> 8.6 | I23: Kishor | J23: Apr-May-Jun-25 | K23: 202504 | X23: 1 | Y23: 1 | Z23: 1
A24: 37 | B24: Exit_Approval reassignment for Clearance | C24: 1931 | D24: NON-OCR | E24: N | F24: Y | G24: Complex | H24: =VLOOKUP(_xlfn.CONCAT(D24,G24),'Estimation Guidelines'!C:L,10,FALSE) -> 8.6 | I24: Rutuja | J24: Jun-Jul-Aug-25 | K24: 202506 | Z24: 1 | AA24: 1 | AB24: 1
A25: 7 | B25: Data Change – Data Change | C25: 6804 | D25: NON-OCR | E25: N | F25: Y | G25: Medium | H25: =VLOOKUP(_xlfn.CONCAT(D25,G25),'Estimation Guidelines'!C:L,10,FALSE) -> 5.8 | I25: Kishor | J25: 45839 | K25: 202507 | AA25: 1
A26: 40 | B26: JD linkage | C26: 4037 | D26: NON-OCR | E26: N | F26: Y | G26: Medium | H26: =VLOOKUP(_xlfn.CONCAT(D26,G26),'Estimation Guidelines'!C:L,10,FALSE) -> 5.8 | I26: Kishor | J26: Aug-Sep-25 | K26: 202508 | AB26: 1 | AC26: 1
A27: 39 | B27: Incident Class. / Data / sync issue | C27: 1926 | D27: NON-OCR | E27: N | F27: Y | G27: Medium | H27: =VLOOKUP(_xlfn.CONCAT(D27,G27),'Estimation Guidelines'!C:L,10,FALSE) -> 5.8 | I27: Rutuja | J27: Sep-Oct-25 | K27: 202509 | AC27: 1 | AD27: 1
A28: 42 | B28: Job Data Update (Resignation, Separation and Transfer) | C28: 4381 | D28: NON-OCR | E28: N | F28: Y | G28: Medium | H28: =VLOOKUP(_xlfn.CONCAT(D28,G28),'Estimation Guidelines'!C:L,10,FALSE) -> 5.8 | I28: Kishor | J28: Oct-Nov-25 | K28: 202510 | AD28: 1 | AE28: 1
A29: 43 | B29: Mobility_HR Initiated Transfer | C29: 7125 | D29: NON-OCR | E29: N | F29: Y | G29: Medium | H29: =VLOOKUP(_xlfn.CONCAT(D29,G29),'Estimation Guidelines'!C:L,10,FALSE) -> 5.8 | I29: Rutuja | J29: Jan-Feb-26 | K29: 202511 | AE29: 1 | AF29: 1
A30: 8 | B30: External Hire Poornata ID creation | C30: 5170 | D30: NON-OCR | E30: N | F30: Y | G30: Complex | H30: =VLOOKUP(_xlfn.CONCAT(D30,G30),'Estimation Guidelines'!C:L,10,FALSE) -> 8.6 | I30: Kishor | J30: Nov-Dec-25 | K30: 202512 | AF30: 1 | AG30: 1
A31: 10 | B31: Poornata ID Creation (Add a Person) - Excel Template | C31: 5159 | D31: NON-OCR | E31: N | F31: Y | G31: Complex | H31: =VLOOKUP(_xlfn.CONCAT(D31,G31),'Estimation Guidelines'!C:L,10,FALSE) -> 8.6 | I31: Kishor | J31: Mar-Apr-26 | K31: 202601 | AG31: 1 | AH31: 1 | AI31: 1
A32: 44 | B32: New/ Old Event | C32: 2192 | D32: NON-OCR | E32: N | F32: Y | G32: Complex | H32: =VLOOKUP(_xlfn.CONCAT(D32,G32),'Estimation Guidelines'!C:L,10,FALSE) -> 8.6 | I32: Kishor | J32: Dec-Jan-Feb-26 | K32: 202602 | AH32: 1 | AI32: 1
A33: 45 | B33: Onboarding Initiation | C33: 2676 | D33: NON-OCR | E33: N | F33: Y | G33: Complex | H33: =VLOOKUP(_xlfn.CONCAT(D33,G33),'Estimation Guidelines'!C:L,10,FALSE) -> 8.6 | I33: Rutuja | J33: Mar-Apr-May-26 | K33: 202603 | AI33: 1 | AJ33: 1 | AK33: 1
A34: 1 | B34: Data Change – Override Manager | C34: 6089 | D34: NON-OCR | E34: Y | F34: Y | G34: Medium | I34: Varun
A35: 2 | B35: Data Change – Use Position Reports To | C35: 3933 | D35: NON-OCR | E35: Y | F35: Y | G35: Simple | I35: Varun
A36: 3 | B36: Job Architecture | C36: 10692 | D36: NON-OCR | E36: Y | F36: Y | G36: Medium | I36: Varun
A37: 5 | B37: Data Change – Override Person Job Band | C37: 4 | D37: NON-OCR | F37: N
A38: 6 | B38: Data Change – Use Position Job Band | C38: 7 | D38: NON-OCR | F38: N
A39: 9 | B39: Poornata ID creation (Add a Person - Smart HR) | C39: 1057 | D39: NON-OCR | F39: N | G39: Medium
A40: 11 | B40: Poornata ID Creation (Add POI/CWR) | C40: 573 | D40: NON-OCR | F40: N | G40: Complex
...

Sheet OverallProcesses
A2: Final category | B2: Final catalog | C2: Total
A3: WFA | B3: ABCap Prospective Hire Link Creation | C3: 43
B4: Bank Data Update | C4: 2876
B5: Compensation Update | C5: 78207
B6: Confirmation | C6: 959
B7: Confirmation with Payrate Change | C7: 1204
B8: Confirmation with Payrate Change and Promotion | C8: 29
B9: Data Change - Data Change | C9: 6785
B10: Data Change - Override Manager | C10: 5918
B11: Data Change - Override Person Job Band | C11: 16
B12: Data Change - Use Position Job Band | C12: 10
B13: Data Change - Use Position Reports To | C13: 3657
B14: Exit_Approval reassignment for Clearance | C14: 1920
B15: Exit_Approval reassignment for Resignation | C15: 168
... B55: Personal Data | C55: 1
A56: WFA Total | C56: 212016
A57: JAE | B57: ABCap Prospective Hire Link Creation | C57: 36
B58: Compensation Update | C58: 4
B59: Confirmation | C59: 921
B60: Data Change - Data Change | C60: 19
B61: Data Change - Override Manager | C61: 99
B62: Data Change - Use Position Reports To | C62: 14
B63: Incident Class. / Admin / Tech Issues | C63: 1
B64: JD linkage | C64: 4009
B65: Job Code Creation | C65: 2
B66: Job Data Update | C66: 1372
B67: Job Data Update (Resignation, Separation and Transfer) | C67: 33
B68: Leave Balance upload | C68: 65
B69: Mobility_HR Initiated Transfer | C69: 5
... B78: JAE and Position Management | C78: 16
A79: JAE Total | C79: 32069
A80: TM | B80: Business PMS Calendar Update | C80: 0
B81: Cancellation of Potential Assessment document | C81: 788
B82: Compensation Update | C82: 0
B83: Creation of performance document | C83: 20
B84: Domo Reports Access Request (GVC- Elearning) | C84: 31
B85: Exit_Resignation/Separation/ Termination | C85: 2
B86: Incident Class. / Access Issues | C86: 0
B87: Initiate Background Verification Check | C87: 0
B88: Initiate EP File Check | C88: 0
...

Sheet Inventory
A1: Sr# | B1: Transaction Name | C1: Priority on Symphony (Filter Used) | D1: Average Transactions (Annual) | E1: Average Transactions (Monthly) | F1: AHT Manual (In Min's) | G1: Total AHT (HR) | H1: Frequency | I1: SLA | J1: Response SLA Resolution SLA (Annual) | K1: Processing Hours | L1: Weekend BOT Run | M1: Peak Period | N1: RPA Priority | O1: Applications Name | P1: Tickets Containing OCR Documents (%) | Q1: OCR Required | R1: Complexity | S1: Impact | T1: RPA AHT (Per Transaction) | U1: Total Hrs (Daily) | V1: Status
A2: 1 | B2: Data Change – Override Manager | C2: WFA_DTCHNG_OVRMGR-MEDIUM | D2: 6089 | E2: =D2/12 -> 507.41667 | F2: 6 | G2: =(E2*F2)/60 -> 50.741667 | H2: Daily | I2: 24 Hrs | J2: 98.81% 99.90% | K2: Business Hours | L2: Yes | M2: March | N2: 1 | O2: Symphony, PeopleSoft Read from Excel | P2: 0.3 | Q2: Non OCR | R2: Medium | S2: High | V2: Deployed in Production
A3: 2 | B3: Data Change – Use Position Reports To | C3: WFA_DTCHNG_USEPOMGR_MEDIUM | D3: 3933 | E3: =D3/12 -> 327.75 | F3: 5 | G3: =(E3*F3)/60 -> 27.3125 | H3: Daily | I3: 24 Hrs | J3: 99.81% 99.90% | K3: Business Hours | L3: Yes | M3: Jun-Aug | N3: 2 | O3: Symphony, PeopleSoft Read from Excel | P3: 0.3 | Q3: Non OCR | R3: Simple | S3: High | V3: Deployed in Production
A4: 3 | B4: Job Architecture | C4: Job Arch_Position_Creation/Updation_High (0-20) | D4: 10692 | E4: =D4/12 -> 891 | F4: 5 | G4: =(E4*F4)/60 -> 74.25 | H4: Daily | I4: 12 Hrs | J4: NA | K4: Business Hours | L4: Yes | M4: Mar-Jun | N4: 3 | O4: Symphony, PeopleSoft Read from Excel | P4: 0 | Q4: Non OCR | R4: Medium | S4: High | V4: Deployed in Production
A5: 4 | B5: Job Description Update | C5: JAE and PM_JDLink_Low(1-330+) | D5: 7168 | E5: =D5/12 -> 597.33333 | F5: 10 | G5: =(E5*F5)/60 -> 99.555556 | H5: Daily | I5: 12 Hrs | J5: NA | K5: Business Hours | L5: Yes | M5: May-Jul | N5: 4 | O5: Symphony, PeopleSoft Read from Excel | P5: 0 | Q5: Non OCR | R5: Complex | S5: High | V5: KT
A6: 5 | B6: Data Change – Override Person Job Band | C6: WFA_DTCHNG_OVRJB_MEDIUM | D6: 4 | E6: =D6/12 -> 0.33333333 | G6: =(E6*F6)/60 -> 0 | I6: 24 Hrs | N6: 5 | O6: Symphony, PeopleSoft Read from Excel | P6: 0 | Q6: Non OCR
A7: 6 | B7: Data Change – Use Position Job Band | C7: WFA_DTCHNG_USPOJB_MEDIUM | D7: 7 | E7: =D7/12 -> 0.58333333 | G7: =(E7*F7)/60 -> 0 | I7: 24 Hrs | N7: 6 | O7: Symphony, PeopleSoft Read from Excel | P7: 0 | Q7: Non OCR
A8: 7 | B8: Data Change – Data Change | C8: WFA_DTCHNG_DTCHNG_MEDIUM | D8: 1372 | E8: =D8/12 -> 114.33333 | G8: =(E8*F8)/60 -> 0 | I8: 24 Hrs | N8: 7 | O8: Symphony, PeopleSoft Read from Excel | P8: 0 | Q8: Non OCR
A9: 8 | B9: External Hire Poornata ID creation | C9: WFA_ExtHireB_High (80 or Less) | D9: 5170 | E9: =D9/12 -> 430.83333 | G9: =(E9*F9)/60 -> 0 | H9: Daily | I9: 12 Hrs | N9: 8 | O9: Symphony, PeopleSoft Read from Excel | P9: 0 | Q9: Non OCR | R9: Complex | S9: High
B10: Poornata ID creation (Add a Person - Smart HR) | C10: WFA_SmrtAddprsn_High | D10: 1057 | E10: =D10/12 -> 88.083333 | F10: 5 | G10: =ROUNDUP((E10*F10)/60,2) -> 7.35 | H10: On Demand | I10: 12 Hrs - If volume is less than 30 84 Hrs - if Volum is greater than 30 | O10: Symphony, PeopleSoft Read from Excel | Q10: Non OCR | R10: Medium | S10: Low
B11: Poornata ID Creation (Add a Person) - Excel Template | C11: WFA_Addperson_High (85 or Less) | D11: 5159 | E11: =D11/12 -> 429.91667 | F11: 20 | G11: =ROUNDUP((E11*F11)/60,2) -> 143.31 | H11: On Demand | I11: 12 Hrs - If volume is less than 30 84 Hrs - if Volum is greater than 30 | O11: Symphony, PeopleSoft Read from Excel | Q11: Non OCR | R11: Complex | S11: High
B12: Poornata ID Creation (Add POI/CWR) | C12: WFA_AddaPersnPOI/CWR_High (80 or Less) | D12: 573 | E12: =D12/12 -> 47.75 | F12: 10 | G12: =ROUNDUP((E12*F12)/60,2) -> 7.96 | H12: On Demand | I12: 12 Hrs - If volume is less than 30 84 Hrs - if Volum is greater than 30 | O12: Symphony, PeopleSoft Read from Excel | Q12: Non OCR | R12: Complex | S12: Low
A13: 9 | B13: Job Data Update (Confirmation/Confirmation with pay rate change/Mobility) | D13: 10119 | E13: =D13/12 -> 843.25 | F13: 5 | G13: =ROUNDUP((E13*F13)/60,2) -> 70.28 | H13: Daily | I13: 12 Hrs | K13: Business Hours | O13: Symphony, PeopleSoft Read from Excel | P13: 0.6 | Q13: OCR | R13: Complex | S13: High
A14: 10 | B14: Personal Data Update (Excluding Bulk volume-43,274) | C14: WFA_Prsnl_Low (1 to 240) | D14: 14504 | E14: =D14/12 -> 1208.6667 | F14: 10 | G14: =ROUNDUP((E14*F14)/60,2) -> 201.45 | H14: Daily | I14: 36 Hrs - If volume is less than 30 84 Hrs - if Volum is greater than 30 | K14: Business Hours | O14: Symphony, PeopleSoft Read from Excel | P14: 0.2 | Q14: OCR | R14: Complex | S14: High
A15: 11 | B15: Compensation Update (Excluding bulk volume-71,968) | C15: WFA_JobUpd(Comp)_High ( 70 or Less) | D15: 7232 | E15: =D15/12 -> 602.66667 | F15: 15 | G15: =ROUNDUP((E15*F15)/60,2) -> 150.67 | H15: Daily | I15: 12 Hrs - If volume is less than 30 84 Hrs - if Volum is greater than 30 | K15: Business Hours | O15: Symphony, PeopleSoft Read from document/Excel | P15: 0.2 | Q15: OCR | R15: Complex | S15: High
A16: 12 | B16: Creation of Potential Assessment Document | C16: TM_CrtPAD_High (1 to 30) | D16: 5337 | E16: =D16/12 -> 444.75 | F16: 5 | G16: =ROUNDUP((E16*F16)/60,2) -> 37.07 | H16: Daily | K16: Business Hours | O16: Symphony, PeopleSoft Read from document/Excel | P16: 0 | Q16: Non OCR | R16: check with Anuja | S16: High
A17: 13 | B17: Poornata ID Creation (Add a Person) (Proposed Process Change) | D17: 8925 | E17: =D17/12 -> 743.75 | F17: 25 | G17: =ROUNDUP((E17*F17)/60,2) -> 309.9 | I17: 12 Hrs | O17: Symphony, PeopleSoft Read from document/Excel | P17: 0.9 | Q17: OCR | R17: Complex
A18: 14 | B18: Bank Data Update | C18: WFA_BankDataUpdate_1-30_High | D18: 3695 | E18: =D18/12 -> 307.91667 | F18: 8 | G18: =ROUNDUP((E18*F18)/60,2) -> 41.06 | H18: Weekly | K18: Business Hours | M18: Every Month 10th to 25th | O18: Symphony, PeopleSoft Read from document/Excel | P18: 0.9 | Q18: OCR | R18: Medium | S18: Medium
A19: 15 | B19: Poornata ID creation (Through External Hire) – QC action and update if missing data-Proposed process change | D19: 5854 | E19: =D19/12 -> 487.83333 | F19: 25 | G19: =ROUNDUP((E19*F19)/60,2) -> 203.27 | I19: 12 Hrs | O19: Onboarding tool, PeopleSoft Read from document/Excel | P19: 0.9 | Q19: OCR
A20: 16 | B20: Education Data | C20: ESS_Edu_Low | D20: 2981 | E20: =D20/12 -> 248.41667 | F20: 7 | G20: =ROUNDUP((E20*F20)/60,2) -> 28.99 | H20: Daily | I20: 36 Hrs | K20: Business Hours | O20: Symphony, PeopleSoft Read from document/Excel | P20: 0.9 | Q20: OCR | R20: Complex | S20: High
A21: 17 | B21: National ID, PAN, Aadhar, Passport, Visa, Address | C21: ESS_AddChg_Low ESS_Ppst_Low ESS_Visa_Low ESS_NationID_High | D21: 495 | E21: =D21/12 -> 41.25 | F21: 10 | G21: =ROUNDUP((E21*F21)/60,2) -> 6.88 | H21: Weekly | I21: 36 Hrs | K21: Business Hours | O21: Symphony, PeopleSoft Read from document/Excel | P21: 0.9 | Q21: OCR | R21: Medium | S21: High
A22: 18 | B22: Learning Session creation | C22: LM_Crt_Sess_Medium (1 to 50) | D22: 1277 | E22: =D22/12 -> 106.41667 | F22: 20 | G22: =ROUNDUP((E22*F22)/60,2) -> 35.48 | H22: Weekly | I22: 24 Hrs | K22: Business Hours | O22: Symphony, CSOD Read from Excel | P22: 0 | Q22: Non OCR | S22: Medium
A23: 19 | B23: Leave Balance upload | C23: WFA_Leave Balance upload_Medium | D23: 4243 | E23: =D23/12 -> 353.58333 | F23: 12 | G23: =ROUNDUP((E23*F23)/60,2) -> 70.72 | H23: Monthly | I23: 24 Hrs | K23: Business Hours | M23: Every End Activity - Dec to Jan | O23: Symphony, PeopleSoft Read from Excel | P23: 0 | Q23: Non OCR | R23: Complex | S23: Medium
A24: 20 | B24: BGV initiation and Report upload Initiate – 20 mins Report upload 10 mins | C24: TS_BGV_Medium (1-30) | D24: 5228 | E24: =D24/12 -> 435.66667 | F24: 30 | G24: =ROUNDUP((E24*F24)/60,2) -> 217.84 | H24: Daily | I24: 24 Hrs | K24: Business Hours | O24: On boarding, One drive, Outlook and DMS | P24: 0 | Q24: Non OCR | R24: Complex | S24: High
G25: =ROUNDUP((E25*F25)/60,2) -> 0
A26: 21 | B26: FnF Settlement | D26: 12829 | E26: =D26/12 -> 1069.0833 | G26: =ROUNDUP((E26*F26)/60,2) -> 0 | O26: Excel, Payroll system | Q26: non OCR | R26: Complex | S26: High
A27: 22 | B27: Maker-Checker - ACR Letter | G27: =ROUNDUP((E27*F27)/60,2) -> 0 | O27: People Soft, PDF, Excel | Q27: non OCR | R27: Complex | S27: High
A28: 23 | B28: Ticket Creater | D28: 48701 | E28: =D28/12 -> 4058.4167 | G28: =ROUNDUP((E28*F28)/60,2) -> 0 | H28: Daily | K28: Business Hours | L28: Yes | M28: year | N28: 1 | O28: Symphony, PeopleSoft Read from Excel | Q28: non OCR | V28: Deployed in Production | X28: 44643 | Y28: =X28/11 -> 4058.4545 | Z28: =Y28*12 -> 48701.455
A29: 24 | B29: Talent Profile Creation BOT | D29: 5310 | E29: 442.5 | G29: =ROUNDUP((E29*F29)/60,2) -> 0 | H29: Based on requirement | K29: Business Hours | L29: Yes | M29: year | N29: 2 | O29: PeopleSoft Read from Excel,PDF | Q29: non OCR | V29: Deployed in Production
A30: 25 | B30: Poornata Status update - SR Update in Transaction | D30: 53182 | E30: 4431.8333 | G30: =ROUNDUP((E30*F30)/60,2) -> 0 | H30: Daily | K30: Business Hours | L30: Yes | M30: year | N30: 1 | O30: PeopleSoft Read from Excel | Q30: non OCR | V30: Deployed in Production
A31: 26 | B31: Audit Sampling | G31: =ROUNDUP((E31*F31)/60,2) -> 0 | H31: Based on requirement | K31: Business Hours | L31: Yes | M31: year | N31: 2 | O31: Read from Excel | Q31: non OCR | V31: Deployed in Production
A32: 27 | B32: Create a Dashboard | G32: =ROUNDUP((E32*F32)/60,2) -> 0 | H32: Daily | K32: Business Hours | L32: Yes | M32: year | N32: 1 | O32: Read from Excel,Outlook | Q32: non OCR
A33: 28 | B33: Cement ticket creator | G33: =ROUNDUP((E33*F33)/60,2) -> 0 | H33: Daily | K33: Business Hours | L33: Yes | M33: year | N33: 1 | O33: Symphony, PeopleSoft Read from Excel | Q33: non OCR
A34: 27 | B34: Potential Assesment | C34: Was built on Priority | G34: =ROUNDUP((E34*F34)/60,2) -> 0 | H34: Based on requirement | K34: Business Hours | L34: Yes | M34: Oct-Dec | N34: 1 | O34: Symphony, PeopleSoft Read from Excel | Q34: non OCR | V34: Deployed in Production
A35: 28 | B35: PH Link Initiation (ABCAP) | C35: TS_Onbrd_High | D35: 6316 | E35: =D35/12 -> 526.33333 | F35: 10 | H35: Daily | I35: 12 Hrs | K35: Business Hours | L35: Yes | M35: year | O35: Symphony, ALT Recruit | Q35: OCR | R35: Complex | S35: High
B36: Total | D36: =SUM(D2:D24) -> 111114 | F36: =SUM(F2:F24) -> 233 | T36: =SUM(T2:T24) -> 0 | U36: =SUM(U2:U24) -> 0

Sheet Sheet1
A1: Automation Required | B1: Y
A3: Count of UseCase Name | B3: Column Labels
A4: RPA UseCases | B4: Complex | C4: Medium | D4: Simple | E4: Grand Total
A5: NON-OCR | B5: 15 | C5: 12 | D5: 5 | E5: 32
A6: OCR | B6: 8 | C6: 1 | E6: 9
A7: Grand Total | B7: 23 | C7: 13 | D7: 5 | E7: 41

Sheet Sheet2
A3: Row Labels | B3: Sum of Average Transactions (Annual)
A4: NON-OCR | B4: 284393
A5: OCR | B5: 174269
A6: (blank)
A7: Grand Total | B7: 458662

Sheet Complexity Guidelines
A2: Parameter | B2: Simple | C2: Medium | D2: Complex
A3: Definitions | B3: Tasks does not have any manual non digital inputs like | C3: - Tasks have a maximum of simple binary decision-making steps like Yes/No etc. | D3: - Tasks have handoffs between activities and the linkages have to be accurately managed.
B4: - Scanned images | C4: - Data Transformation | D4: - Nested Tasks / Activities
B5: - Unstructured data | C5: - Application based Authentication Handing | D5: - Multiple application interfaces
B6: - Handwritten documents etc.
A7: Number of applications used in the task? | B7: 3 Max | C7: 4 Max | D7: 5 Max
A8: (MS Excel, Outlook, SAP or a web browser, DB, Custom Application etc)
A9: - In case of SAP / Web application, each tcode / screen or web page will be treated as a separate application
A10: How many fields does the task have overall? (Sum the number of fields on all screens involved) | B10: 01-35 | C10: 35-75 | D10: 75-125
A11: What kind of decisions are taken to complete the task | B11: The tasks is linear - there are no decisions to be taken | C11: The tasks involves simple decisions (yes/no type) | D11: The tasks involves complex & multiple decisions
A12: Number of rules/conditions | B12: 5 | C12: 6 | D12: 12
A13: Multi Factor Authentication / Captcha / QR Code | B13: No | C13: Yes | D13: Yes
A14: Any task which cannot accomplish without Human supervision / checks (Example: Approvals, Digital Signature or any Complex decision) | B14: No | C14: No | D14: Yes
A15: Are any of the applications accessed via Citrix/VDI? | B15: No | C15: No | D15: Yes
A16: Is your input data only digital? | B16: Yes | C16: Yes | D16: Yes
A17: Input Channels Considered (Outlook, Files, ERP, Web downloads) | B17: 2 | C17: 4 | D17: 6
A18: Any task that require pattern recognition / Sentiment & Emotion Analysis (Example: Any decision making activity based on email received or any feedback survey) | B18: No | C18: No | D18: Yes
A19: Is your input data is structured/Unstructured? | B19: Structured Excel, Word, Text Files | C19: Form Based PDF, Fillable Word Forms | D19: Unstructured Documents, Scanned Images, Handwritten Documents
A20: Number of Files/file Types processed (Excel, Google Sheets, Word, .csv, .txt) | B20: 3 | C20: 5 | D20: 7
A21: Exception handling - Application and Logic | B21: 6 Max | C21: 10 Max | D21: 15 Max

Sheet ROI
A2: Use Case Meta Data | I2: Existing Manual Daily Cost | O2: Savings | Q2: BOT Daily Cost | Z2: ROI
A3: #Priority | B3: UseCase | C3: Already in Production | D3: AverageTransactions(Annual) | E3: OCR/NON-OCR | F3: Frequency | G3: Complexity | H3: Manual MHT / AHT in Min /Transaction | I3: Manual FTE Required/Day | J3: FTE Cost (Per Day) | K3: Seat Cost (Per Day) | L3: Employee Cost (Others - Paid by )* Per Day | M3: Other OPEX Cost*Per Day | N3: Total Cost (Per Day) | O3: FTE Saved/Day | P3: BOT MHT / AHT (Min) | Q3: BOT FTE Required / Day | R3: FTE Cost After BOT Implementation(Per Day) | S3: Infra Cost (Per Day) | T3: License Cost (Per Day) | W3: Development & Support | Y3: Total Cost (Excluding Development & Creater Cost) | Z3: ROI (Per Day) | AA3: ROI In Percent
T4: Runner | U4: Creater | V4: OCR | W4: Development | X4: Support
A6: Overall Program ROI

Sheet License
A2: Total License | E2: Bots Planned | F2: Annual Transactions | G2: Including 20% Buffer Transactions | H2: Monthly Transactions | I2: Daily Transactions | J2: Daily Total time (Mins)
A3: Runner License | B3: 0 | E3: 23 | F3: =SUM(ROI!D5:D5) -> 0 | G3: =(F3*20%)+F3 -> 0 | H3: =G3/12 -> 0 | I3: =H3/30 -> 0 | J3: =I3*AVERAGE(ROI!P5:P5) -> #DIV/0!
A4: Creator | B4: 0 | E4: Mins in 24 hours | J4: 1440
E5: Runner Licenses | J5: =J3/J4 -> #DIV/0!
A6: Allocated License | E6: Evaluate every 3month based on Bots in production
A7: Runner License | B7: 0 | C7: Existing Prod. Bots
C8: Ticket Creation
A10: Available | E10: Bots Planned | F10: Annual Transactions | G10: Including 20% Buffer Transactions | H10: Monthly Transactions | I10: Daily Transactions | J10: Daily Total time (Mins)
A11: Runner License | B11: 1 | E11: 23 | F11: =SUM(ROI!D5:D5) -> 0 | G11: =(F11*20%)+F11 -> 0 | H11: =G11/12 -> 0 | I11: =H11/30 -> 0 | J11: =I11*AVERAGE(ROI!P5:P5) -> #DIV/0!
B12: 1 | E12: Mins in 12 hours | J12: 720
A13: Creator | B13: 0 | C13: Developer 1 | E13: Runner Licenses | J13: =J11/J12 -> #DIV/0!
B14: 0 | C14: Developer 2 | E14: Evaluate every 3month based on Bots in production
B15: 0 | C15: Developer 3
B16: 0 | C16: Developer 4

Sheet RPA RoadMap
D1: =SUBTOTAL(9,D4:D500) -> 478662 | H1: =SUBTOTAL(9,H4:H500) -> 54.695638 | I1: =SUBTOTAL(9,I4:I500) -> 30.732741 | J1: =SUBTOTAL(9,J4:J500) -> 28132600 | K1: =SUBTOTAL(9,K4:K500) -> 18439645 | L1: =K1/J1 -> 0.65545469 | M1: >1500
B2: RPA Use Cases | S2: 2024 | AB2: 2025 | AN2: 2026
A3: Sr# | B3: UseCase Name | D3: Average Transactions (Annual) | E3: OCR / NON-OCR | F3: Frequency | G3: AHT (Manual) Mins | H3: FTE Manual | I3: FTE Saved | J3: FTE Manual Cost (INR) | K3: FTE Saved Cost (INR) | L3: Already in production | M3: Automation Required | N3: RPA Complexity | O3: Estimated Efforts(Weeks) | P3: Developer | Q3: Timeline | R3: Smonth | S3: Apr | T3: May | U3: Jun | V3: Jul | W3: Aug | X3: Sep | Y3: Oct | Z3: Nov | AA3: Dec | AB3: Jan | AC3: Feb | AD3: Mar | AE3: Apr | AF3: May | AG3: Jun | AH3: Jul | AI3: Aug | AJ3: Sep | AK3: Oct | AL3: Nov | AM3: Dec | AN3: Jan | AO3: Feb | AP3: Mar | AQ3: Apr | AR3: May
A4: 4 | B4: Job Description Update | D4: 7168 | E4: NON-OCR | F4: =VLOOKUP('RPA RoadMap'!$B4,Inventory!$B$1:$N$38,7,FALSE) -> Daily | G4: =VLOOKUP('RPA RoadMap'!$B4,Inventory!$B$1:$N$38,5,FALSE) -> 10 | H4: =((D4/200)*G4)/60/6.5 -> 0.91897436 | I4: =H4*0.6 -> 0.55138462 | J4: =H4*600000 -> 551384.62 | K4: =I4*600000 -> 330830.77 | L4: N | M4: Y | N4: Complex | O4: =VLOOKUP(_xlfn.CONCAT(E4,N4),'Estimation Guidelines'!C:L,10,FALSE) -> 8.6 | P4: Kishor | Q4: Mar-April | R4: 202403 | S4: 1
A5: 20 | B5: National ID, PAN, Aadhar, Passport, Visa, Address | D5: 9845 | E5: OCR | F5: =VLOOKUP('RPA RoadMap'!$B5,Inventory!$B$1:$N$38,7,FALSE) -> Weekly | G5: =VLOOKUP('RPA RoadMap'!$B5,Inventory!$B$1:$N$38,5,FALSE) -> 10 | H5: =((D5/200)*G5)/60/6.5 -> 1.2621795 | I5: =H5*0.6 -> 0.75730769 | J5: =H5*600000 -> 757307.69 | K5: =I5*600000 -> 454384.62 | L5: N | M5: Y | N5: Complex | O5: =VLOOKUP(_xlfn.CONCAT(E5,N5),'Estimation Guidelines'!C:L,10,FALSE) -> 11.6 | P5: Rutuja , RPADEV01 | Q5: April - May-June-July | R5: 202404 | S5: 1 | T5: 1 | U5: 1 | V5: 1
A6: 17 | B6: Bank Data Update | D6: 3695 | E6: OCR | F6: =VLOOKUP('RPA RoadMap'!$B6,Inventory!$B$1:$N$38,7,FALSE) -> Weekly | G6: =VLOOKUP('RPA RoadMap'!$B6,Inventory!$B$1:$N$38,5,FALSE) -> 8 | H6: =((D6/200)*G6)/60/6.5 -> 0.37897436 | I6: =H6*0.8 -> 0.30317949 | J6: =H6*600000 -> 227384.62 | K6: =I6*600000 -> 181907.69 | L6: N | M6: Y | N6: Medium | O6: =VLOOKUP(_xlfn.CONCAT(E6,N6),'Estimation Guidelines'!C:L,10,FALSE) -> 8.8 | P6: Rutuja , RPADEV01 | Q6: April - May-June-July | R6: 202404 | S6: 1 | T6: 1 | U6: 1 | V6: 1
A7: 19 | B7: Education Data | D7: 2981 | E7: OCR | F7: =VLOOKUP('RPA RoadMap'!$B7,Inventory!$B$1:$N$38,7,FALSE) -> Daily | G7: =VLOOKUP('RPA RoadMap'!$B7,Inventory!$B$1:$N$38,5,FALSE) -> 7 | H7: =((D7/200)*G7)/60/6.5 -> 0.26752564 | I7: =H7*0.6 -> 0.16051538 | J7: =H7*600000 -> 160515.38 | K7: =I7*600000 -> 96309.231 | L7: N | M7: Y | N7: Complex | O7: =VLOOKUP(_xlfn.CONCAT(E7,N7),'Estimation Guidelines'!C:L,10,FALSE) -> 11.6 | P7: Rutuja , RPADEV01 | Q7: April - May-June-July | R7: 202404 | S7: 1 | T7: 1 | U7: 1 | V7: 1
A8: 24 | B8: FnF Settlement | D8: 12829 | E8: NON-OCR | F8: Monthly | G8: 10 | H8: =((D8/200)*G8)/60/6.5 -> 1.6447436 | I8: =H8*0.6 -> 0.98684615 | J8: =H8*600000 -> 986846.15 | K8: =I8*600000 -> 592107.69 | L8: N | M8: Y | N8: Complex | O8: =VLOOKUP(_xlfn.CONCAT(E8,N8),'Estimation Guidelines'!C:L,10,FALSE) -> 8.6 | P8: Ganesh / Tushar | Q8: April - May | R8: 202404 | S8: 1 | T8: 1
A9: 38 | B9: Holiday Schedule upload | D9: 10287 | E9: NON-OCR | F9: Monthly | G9: 10 | H9: =((D9/200)*G9)/60/6.5 -> 1.3188462 | I9: =H9*0.9 -> 1.1869615 | J9: =H9*600000 -> 791307.69 | K9: =I9*600000 -> 712176.92 | L9: N | M9: Y | N9: Simple | O9: =VLOOKUP(_xlfn.CONCAT(E9,N9),'Estimation Guidelines'!C:L,10,FALSE) -> 4.8 | P9: Kishor | Q9: May | R9: 202405 | T9: 1
A10: 41 | B10: Job Data Update | D10: 45835 | E10: NON-OCR | F10: Daily | G10: 10 | H10: =((D10/200)*G10)/60/6.5 -> 5.8762821 | I10: =H10*0.8 -> 4.7010256 | J10: =H10*600000 -> 3525769.2 | K10: =I10*600000 -> 2820615.4 | L10: N | M10: Y | N10: Medium | O10: =VLOOKUP(_xlfn.CONCAT(E10,N10),'Estimation Guidelines'!C:L,10,FALSE) -> 5.8 | P10: Kishor | Q10: June- July | R10: 202406 | U10: 1 | V10: 1
A11: 25 | B11: Maker-Checker - ACR Letter | D11: 5000 | E11: NON-OCR | F11: Annual | G11: 10 | H11: =((D11/200)*G11)/60/6.5 -> 0.64102564 | I11: =H11*0.6 -> 0.38461538 | J11: =H11*600000 -> 384615.38 | K11: =I11*600000 -> 230769.23 | L11: N | M11: Y | N11: Complex | O11: =VLOOKUP(_xlfn.CONCAT(E11,N11),'Estimation Guidelines'!C:L,10,FALSE) -> 8.6 | P11: Ganesh / Tushar | Q11: June- July -Aug | R11: 202406 | U11: 1 | V11: 1 | W11: 1
A12: 33 | B12: PH Link Initiation (ABCAP) | D12: 111114 | E12: OCR | F12: =VLOOKUP('RPA RoadMap'!$B12,Inventory!$B$1:$N$38,7,FALSE) -> Daily | G12: =VLOOKUP('RPA RoadMap'!$B12,Inventory!$B$1:$N$38,5,FALSE) -> 10 | H12: =((D12/200)*G12)/60/6.5 -> 14.245385 | I12: =H12*0.6 -> 8.5472308 | J12: =H12*600000 -> 8547230.8 | K12: =I12*600000 -> 5128338.5 | L12: N | M12: Y | N12: Complex | O12: =VLOOKUP(_xlfn.CONCAT(E12,N12),'Estimation Guidelines'!C:L,10,FALSE) -> 11.6 | P12: Rutuja , RPADEV01 | Q12: Aug-Sep-Oct | R12: 202408 | W12: 1 | X12: 1 | Y12: 1
A13: 16 | B13: Poornata ID Creation (Add a Person) (Proposed Process Change) | D13: 8925 | E13: OCR | F13: Daily | G13: =VLOOKUP('RPA RoadMap'!$B13,Inventory!$B$1:$N$38,5,FALSE) -> 25 | H13: =((D13/200)*G13)/60/6.5 -> 2.8605769 | I13: =H13*0.6 -> 1.7163462 | J13: =H13*600000 -> 1716346.2 | K13: =I13*600000 -> 1029807.7 | L13: N | M13: Y | N13: Complex | O13: =VLOOKUP(_xlfn.CONCAT(E13,N13),'Estimation Guidelines'!C:L,10,FALSE) -> 11.6 | P13: Rutuja , RPADEV01 | Q13: Aug-Sep-Oct | R13: 202408 | W13: 1 | X13: 1 | Y13: 1
A14: 18 | B14: Poornata ID creation (Through External Hire) – QC action and update if missing data-Proposed process change | D14: 5854 | E14: OCR | F14: Daily | G14: =VLOOKUP('RPA RoadMap'!$B14,Inventory!$B$1:$N$38,5,FALSE) -> 25 | H14: =((D14/200)*G14)/60/6.5 -> 1.8762821 | I14: =H14*0.6 -> 1.1257692 | J14: =H14*600000 -> 1125769.2 | K14: =I14*600000 -> 675461.54 | L14: N | M14: Y | N14: Complex | O14: =VLOOKUP(_xlfn.CONCAT(E14,N14),'Estimation Guidelines'!C:L,10,FALSE) -> 11.6 | P14: Rutuja , RPADEV01 | Q14: Aug-Sep-Oct | R14: 202408 | W14: 1 | X14: 1 | Y14: 1
A15: 46 | B15: Position Creation/ Updation/ Deactivation and JD Linkage (Job Arch ???) | D15: 9247 | E15: NON-OCR | F15: Daily | G15: 10 | H15: =((D15/200)*G15)/60/6.5 -> 1.1855128 | I15: =H15*0.8 -> 0.94841026 | J15: =H15*600000 -> 711307.69 | K15: =I15*600000 -> 569046.15 | L15: N | M15: Y | N15: Medium | O15: =VLOOKUP(_xlfn.CONCAT(E15,N15),'Estimation Guidelines'!C:L,10,FALSE) -> 5.8 | P15: Kishor | Q15: Aug-Sep | R15: 202408 | W15: 1 | X15: 1
A16: 15 | B16: Creation of Potential Assessment Document | D16: 5337 | E16: NON-OCR | F16: =VLOOKUP('RPA RoadMap'!$B16,Inventory!$B$1:$N$38,7,FALSE) -> Daily | G16: =VLOOKUP('RPA RoadMap'!$B16,Inventory!$B$1:$N$38,5,FALSE) -> 5 | H16: =((D16/200)*G16)/60/6.5 -> 0.34211538 | I16: =H16*0.6 -> 0.20526923 | J16: =H16*600000 -> 205269.23 | K16: =I16*600000 -> 123161.54 | L16: N | M16: Y | N16: Complex | O16: =VLOOKUP(_xlfn.CONCAT(E16,N16),'Estimation Guidelines'!C:L,10,FALSE) -> 8.6 | P16: Kishor | Q16: Oct-Nov 2024 | R16: 202410 | Y16: 1 | Z16: 1
A17: 13 | B17: Personal Data Update (Excluding Bulk volume-43,274) | D17: 14504 | E17: OCR | F17: =VLOOKUP('RPA RoadMap'!$B17,Inventory!$B$1:$N$38,7,FALSE) -> Daily | G17: =VLOOKUP('RPA RoadMap'!$B17,Inventory!$B$1:$N$38,5,FALSE) -> 10 | H17: =((D17/200)*G17)/60/6.5 -> 1.8594872 | I17: =H17*0.6 -> 1.1156923 | J17: =H17*600000 -> 1115692.3 | K17: =I17*600000 -> 669415.38 | L17: N | M17: Y | N17: Complex | O17: =VLOOKUP(_xlfn.CONCAT(E17,N17),'Estimation Guidelines'!C:L,10,FALSE) -> 11.6 | P17: Rutuja , RPADEV01 | Q17: Nov-Dec-Jan-Feb | R17: 202411 | Z17: 1 | AA17: 1 | AB17: 1
A18: 12 | B18: Job Data Update (Confirmation/Confirmation with pay rate change/Mobility) | D18: 10119 | E18: OCR | F18: =VLOOKUP('RPA RoadMap'!$B18,Inventory!$B$1:$N$38,7,FALSE) -> Daily | G18: =VLOOKUP('RPA RoadMap'!$B18,Inventory!$B$1:$N$38,5,FALSE) -> 5 | H18: =((D18/200)*G18)/60/6.5 -> 0.64865385 | I18: =H18*0.6 -> 0.38919231 | J18: =H18*600000 -> 389192.31 | K18: =I18*600000 -> 233515.38 | L18: N | M18: Y | N18: Complex | O18: =VLOOKUP(_xlfn.CONCAT(E18,N18),'Estimation Guidelines'!C:L,10,FALSE) -> 11.6 | P18: Rutuja , RPADEV01 | Q18: Nov-Dec-Jan-Feb | R18: 202411 | Z18: 1 | AA18: 1 | AB18: 1
A19: 14 | B19: Compensation Update (Excluding bulk volume-71,968) | D19: 7232 | E19: OCR | F19: =VLOOKUP('RPA RoadMap'!$B19,Inventory!$B$1:$N$38,7,FALSE) -> Daily | G19: =VLOOKUP('RPA RoadMap'!$B19,Inventory!$B$1:$N$38,5,FALSE) -> 15 | H19: =((D19/200)*G19)/60/6.5 -> 1.3907692 | I19: =H19*0.6 -> 0.83446154 | J19: =H19*600000 -> 834461.54 | K19: =I19*600000 -> 500676.92 | L19: N | M19: Y | N19: Complex | O19: =VLOOKUP(_xlfn.CONCAT(E19,N19),'Estimation Guidelines'!C:L,10,FALSE) -> 11.6 | P19: Rutuja , RPADEV01 | Q19: Nov-Dec-Jan-Feb | R19: 202411 | Z19: 1 | AA19: 1 | AB19: 1
A20: 22 | B20: Leave Balance upload | D20: 4243 | E20: NON-OCR | F20: =VLOOKUP('RPA RoadMap'!$B20,Inventory!$B$1:$N$38,7,FALSE) -> Monthly | G20: =VLOOKUP('RPA RoadMap'!$B20,Inventory!$B$1:$N$38,5,FALSE) -> 12 | H20: =((D20/200)*G20)/60/6.5 -> 0.65276923 | I20: =H20*0.6 -> 0.39166154 | J20: =H20*600000 -> 391661.54 | K20: =I20*600000 -> 234996.92 | L20: N | M20: Y | N20: Complex | O20: =VLOOKUP(_xlfn.CONCAT(E20,N20),'Estimation Guidelines'!C:L,10,FALSE) -> 8.6 | P20: Kishor | Q20: Dec-Jan | R20: 202412 | AA20: 1 | AB20: 1
A21: 23 | B21: BGV initiation and Report upload Initiate – 20 mins Report upload 10 mins | D21: 5228 | E21: NON-OCR | F21: =VLOOKUP('RPA RoadMap'!$B21,Inventory!$B$1:$N$38,7,FALSE) -> Daily | G21: =VLOOKUP('RPA RoadMap'!$B21,Inventory!$B$1:$N$38,5,FALSE) -> 30 | H21: =((D21/200)*G21)/60/6.5 -> 2.0107692 | I21: =H21*0.6 -> 1.2064615 | J21: =H21*600000 -> 1206461.5 | K21: =I21*600000 -> 723876.92 | L21: N | M21: Y | N21: Complex | O21: =VLOOKUP(_xlfn.CONCAT(E21,N21),'Estimation Guidelines'!C:L,10,FALSE) -> 8.6 | P21: Rutuja | Q21: Feb-Mar 2025 | R21: 202502 | AC21: 1 | AD21: 1
A22: 34 | B22: Cancelling of performance document | D22: 1639 | E22: NON-OCR | F22: Annual | G22: 10 | H22: =((D22/200)*G22)/60/6.5 -> 0.21012821 | I22: =H22*0.8 -> 0.16810256 | J22: =H22*600000 -> 126076.92 | K22: =I22*600000 -> 100861.54 | L22: N | M22: Y | N22: Medium | O22: =VLOOKUP(_xlfn.CONCAT(E22,N22),'Estimation Guidelines'!C:L,10,FALSE) -> 5.8 | P22: Kishor | Q22: Feb-Mar 2025 | R22: 202502 | AC22: 1 | AD22: 1
A23: 35 | B23: Creation and Assigning of Curriculum/ Deeplinks/ Online Courses/ Uploading Videos | D23: 2025 | E23: NON-OCR | F23: Monthly | G23: 10 | H23: =((D23/200)*G23)/60/6.5 -> 0.25961538 | I23: =H23*0.8 -> 0.20769231 | J23: =H23*600000 -> 155769.23 | K23: =I23*600000 -> 124615.38 | L23: N | M23: Y | N23: Medium | O23: =VLOOKUP(_xlfn.CONCAT(E23,N23),'Estimation Guidelines'!C:L,10,FALSE) -> 5.8 | P23: Rutuja | Q23: Apr-May-25 | R23: 202504 | AE23: 1 | AF23: 1
A24: 36 | B24: Creation of performance document | D24: 2013 | E24: NON-OCR | F24: Annual | G24: 10 | H24: =((D24/200)*G24)/60/6.5 -> 0.25807692 | I24: =H24*0.6 -> 0.15484615 | J24: =H24*600000 -> 154846.15 | K24: =I24*600000 -> 92907.692 | L24: N | M24: Y | N24: Complex | O24: =VLOOKUP(_xlfn.CONCAT(E24,N24),'Estimation Guidelines'!C:L,10,FALSE) -> 8.6 | P24: Kishor | Q24: Apr-May-Jun-25 | R24: 202504 | AE24: 1 | AF24: 1 | AG24: 1
A25: 37 | B25: Exit_Approval reassignment for Clearance | D25: 1931 | E25: NON-OCR | F25: Monthly | G25: 10 | H25: =((D25/200)*G25)/60/6.5 -> 0.2475641 | I25: =H25*0.6 -> 0.14853846 | J25: =H25*600000 -> 148538.46 | K25: =I25*600000 -> 89123.077 | L25: N | M25: Y | N25: Complex | O25: =VLOOKUP(_xlfn.CONCAT(E25,N25),'Estimation Guidelines'!C:L,10,FALSE) -> 8.6 | P25: Rutuja | Q25: Jun-Jul-Aug-25 | R25: 202506 | AG25: 1 | AH25: 1 | AI25: 1
A26: 7 | B26: Data Change – Data Change | D26: 6804 | E26: NON-OCR | F26: Daily | G26: 10 | H26: =((D26/200)*G26)/60/6.5 -> 0.87230769 | I26: =H26*0.8 -> 0.69784615 | J26: =H26*600000 -> 523384.62 | K26: =I26*600000 -> 418707.69 | L26: N | M26: Y | N26: Medium | O26: =VLOOKUP(_xlfn.CONCAT(E26,N26),'Estimation Guidelines'!C:L,10,FALSE) -> 5.8 | P26: Kishor | Q26: 45839 | R26: 202507 | AH26: 1
A27: 40 | B27: JD linkage | D27: 4037 | E27: NON-OCR | F27: Daily | G27: 10 | H27: =((D27/200)*G27)/60/6.5 -> 0.5175641 | I27: =H27*0.8 -> 0.41405128 | J27: =H27*600000 -> 310538.46 | K27: =I27*600000 -> 248430.77 | L27: N | M27: Y | N27: Medium | O27: =VLOOKUP(_xlfn.CONCAT(E27,N27),'Estimation Guidelines'!C:L,10,FALSE) -> 5.8 | P27: Kishor | Q27: Aug-Sep-25 | R27: 202508 | AI27: 1 | AJ27: 1
A28: 39 | B28: Incident Class. / Data / sync issue | D28: 1926 | E28: NON-OCR | F28: Daily | G28: 10 | H28: =((D28/200)*G28)/60/6.5 -> 0.24692308 | I28: =H28*0.8 -> 0.19753846 | J28: =H28*600000 -> 148153.85 | K28: =I28*600000 -> 118523.08 | L28: N | M28: Y | N28: Medium | O28: =VLOOKUP(_xlfn.CONCAT(E28,N28),'Estimation Guidelines'!C:L,10,FALSE) -> 5.8 | P28: Rutuja | Q28: Sep-Oct-25 | R28: 202509 | AJ28: 1 | AK28: 1
A29: 42 | B29: Job Data Update (Resignation, Separation and Transfer) | D29: 4381 | E29: NON-OCR | F29: On Demand | G29: 10 | H29: =((D29/200)*G29)/60/6.5 -> 0.56166667 | I29: =H29*0.8 -> 0.44933333 | J29: =H29*600000 -> 337000 | K29: =I29*600000 -> 269600 | L29: N | M29: Y | N29: Medium | O29: =VLOOKUP(_xlfn.CONCAT(E29,N29),'Estimation Guidelines'!C:L,10,FALSE) -> 5.8 | P29: Kishor | Q29: Oct-Nov-25 | R29: 202510 | AK29: 1 | AL29: 1
A30: 43 | B30: Mobility_HR Initiated Transfer | D30: 7125 | E30: NON-OCR | F30: Monthly | G30: 10 | H30: =((D30/200)*G30)/60/6.5 -> 0.91346154 | I30: =H30*0.8 -> 0.73076923 | J30: =H30*600000 -> 548076.92 | K30: =I30*600000 -> 438461.54 | L30: N | M30: Y | N30: Medium | O30: =VLOOKUP(_xlfn.CONCAT(E30,N30),'Estimation Guidelines'!C:L,10,FALSE) -> 5.8 | P30: Rutuja | Q30: Jan-Feb-26 | R30: 202511 | AL30: 1 | AM30: 1
A31: 8 | B31: External Hire Poornata ID creation | D31: 5170 | E31: NON-OCR | F31: =VLOOKUP('RPA RoadMap'!$B31,Inventory!$B$1:$N$38,7,FALSE) -> Daily | G31: 10 | H31: =((D31/200)*G31)/60/6.5 -> 0.66282051 | I31: =H31*0.6 -> 0.39769231 | J31: =H31*600000 -> 397692.31 | K31: =I31*600000 -> 238615.38 | L31: N | M31: Y | N31: Complex | O31: =VLOOKUP(_xlfn.CONCAT(E31,N31),'Estimation Guidelines'!C:L,10,FALSE) -> 8.6 | P31: Kishor | Q31: Nov-Dec-25 | R31: 202512 | AM31: 1 | AN31: 1
A32: 10 | B32: Poornata ID Creation (Add a Person) - Excel Template | D32: 5159 | E32: NON-OCR | F32: =VLOOKUP('RPA RoadMap'!$B32,Inventory!$B$1:$N$38,7,FALSE) -> On Demand | G32: =VLOOKUP('RPA RoadMap'!$B32,Inventory!$B$1:$N$38,5,FALSE) -> 20 | H32: =((D32/200)*G32)/60/6.5 -> 1.3228205 | I32: =H32*0.6 -> 0.79369231 | J32: =H32*600000 -> 793692.31 | K32: =I32*600000 -> 476215.38 | L32: N | M32: Y | N32: Complex | O32: =VLOOKUP(_xlfn.CONCAT(E32,N32),'Estimation Guidelines'!C:L,10,FALSE) -> 8.6 | P32: Kishor | Q32: Mar-Apr-26 | R32: 202601 | AN32: 1 | AO32: 1 | AP32: 1
A33: 44 | B33: New/ Old Event | D33: 2192 | E33: NON-OCR | F33: Daily | G33: 10 | H33: =((D33/200)*G33)/60/6.5 -> 0.28102564 | I33: =H33*0.6 -> 0.16861538 | J33: =H33*600000 -> 168615.38 | K33: =I33*600000 -> 101169.23 | L33: N | M33: Y | N33: Complex | O33: =VLOOKUP(_xlfn.CONCAT(E33,N33),'Estimation Guidelines'!C:L,10,FALSE) -> 8.6 | P33: Kishor | Q33: Dec-Jan-Feb-26 | R33: 202602 | AO33: 1 | AP33: 1
A34: 45 | B34: Onboarding Initiation | D34: 2676 | E34: NON-OCR | F34: Weekly | G34: 10 | H34: =((D34/200)*G34)/60/6.5 -> 0.34307692 | I34: =H34*0.6 -> 0.20584615 | J34: =H34*600000 -> 205846.15 | K34: =I34*600000 -> 123507.69 | L34: N | M34: Y | N34: Complex | O34: =VLOOKUP(_xlfn.CONCAT(E34,N34),'Estimation Guidelines'!C:L,10,FALSE) -> 8.6 | P34: Rutuja | Q34: Mar-Apr-May-26 | R34: 202603 | AP34: 1 | AQ34: 1 | AR34: 1
A35: 1 | B35: Data Change – Override Manager | D35: 6089 | E35: NON-OCR | F35: =VLOOKUP('RPA RoadMap'!$B35,Inventory!$B$1:$N$38,7,FALSE) -> Daily | G35: =VLOOKUP('RPA RoadMap'!$B35,Inventory!$B$1:$N$38,5,FALSE) -> 6 | H35: =(((D35/200)*G35)/60/6.5)*16.67 -> 7.8079715 | L35: Y | M35: Y | N35: Medium | P35: Varun
A36: 2 | B36: Data Change – Use Position Reports To | D36: 3933 | E36: NON-OCR | F36: =VLOOKUP('RPA RoadMap'!$B36,Inventory!$B$1:$N$38,7,FALSE) -> Daily | G36: =VLOOKUP('RPA RoadMap'!$B36,Inventory!$B$1:$N$38,5,FALSE) -> 5 | L36: Y | M36: Y | N36: Simple | P36: Varun
A37: 3 | B37: Job Architecture | D37: 10692 | E37: NON-OCR | F37: =VLOOKUP('RPA RoadMap'!$B37,Inventory!$B$1:$N$38,7,FALSE) -> Daily | G37: =VLOOKUP('RPA RoadMap'!$B37,Inventory!$B$1:$N$38,5,FALSE) -> 5 | L37: Y | M37: Y | N37: Medium | P37: Varun
A38: 5 | B38: Data Change – Override Person Job Band | D38: 4 | E38: NON-OCR | G38: =VLOOKUP('RPA RoadMap'!$B38,Inventory!$B$1:$N$38,5,FALSE) -> 0 | M38: N
A39: 6 | B39: Data Change – Use Position Job Band | D39: 7 | E39: NON-OCR | G39: =VLOOKUP('RPA RoadMap'!$B39,Inventory!$B$1:$N$38,5,FALSE) -> 0 | M39: N
A40: 9 | B40: Poornata ID creation (Add a Person - Smart HR) | D40: 1057 | E40: NON-OCR | G40: =VLOOKUP('RPA RoadMap'!$B40,Inventory!$B$1:$N$38,5,FALSE) -> 5 | M40: N
...

Sheet RPA_SOP_Analysis_ABG Team SI-2
J1: 0.2 | K1: 0.15 | L1: 0.05 | M1: 0.2 | N1: 0.05 | O1: 0.35 | P1: =SUM(J1:O1) -> 1
A2: UseCase Name | B2: Comment | C2: Priority | D2: Average Transactions (Annual) | E2: OCR / NON-OCR | F2: Frequency | G2: AHT (Manual) Mins | H2: Document Referred | I2: SOP Available | J2: Manual Involvement | K2: Complexity | L2: Need Standardisation | M2: Volume | N2: Work with multiple data files | O2: VOC | P2: Scoring Index | Q2: Owner
A3: National ID, PAN, Aadhar, Passport, Visa, Address | C3: 6 | D3: 9845 | E3: OCR | F3: Weekly | G3: 10 | H3: ESS SOP_National ID_SR to IM(2) | I3: Y | J3: 5 | K3: 1 | L3: 5 | M3: 5 | N3: 5 | O3: 5 | P3: =SUM((J$1*$J3),(K$1*$K3),(L$1*$L3)*(M$1*$M3),(N$1*$N3),(O$1*$O3))*100 -> 340 | Q3: Kunal
A4: FnF Settlement | C4: Parallel Execution | D4: 12829 | E4: NON-OCR | F4: Monthly | G4: 10 | I4: N | J4: 5 | K4: 1 | L4: 5 | M4: 5 | N4: 5 | O4: 5 | P4: =SUM((J$1*$J4),(K$1*$K4),(L$1*$L4)*(M$1*$M4),(N$1*$N4),(O$1*$O4))*100 -> 340 | Q4: Kunal
A5: Initiate EJF Verification Process | C5: 1 | D5: =9840+D37 -> 14999 | J5: 5 | K5: 1 | L5: 5 | M5: 4 | N5: 5 | O5: 5 | P5: =SUM((J$1*$J5),(K$1*$K5),(L$1*$L5)*(M$1*$M5),(N$1*$N5),(O$1*$O5))*100 -> 335
A6: AWOO(A world of opprtunity) - OCR | C6: 4 | D6: =150*3*6 -> 2700 | E6: OCR | F6: Yearly | G6: 10 | J6: 5 | K6: 1 | L6: 5 | M6: 2 | N6: 5 | O6: 5 | P6: =SUM((J$1*$J6),(K$1*$K6),(L$1*$L6)*(M$1*$M6),(N$1*$N6),(O$1*$O6))*100 -> 325 | Q6: Asawari
A7: Education Data | C7: 6 | D7: 2981 | E7: OCR | F7: Daily | G7: 7 | H7: ESS SOP_Educational Data_SR to IM | I7: Y | J7: 5 | K7: 1 | L7: 5 | M7: 2 | N7: 5 | O7: 5 | P7: =SUM((J$1*$J7),(K$1*$K7),(L$1*$L7)*(M$1*$M7),(N$1*$N7),(O$1*$O7))*100 -> 325 | Q7: Kunal | R7: SOP not shared but currently working on the project hence aware of the complexity. Sunil will share the SOP soon (as per Swara)
A8: Pratibha - OCR | C8: 3 | D8: =30*3*6 -> 540 | E8: OCR | F8: Yearly | G8: 10 | J8: 5 | K8: 1 | L8: 5 | M8: 1 | N8: 5 | O8: 5 | P8: =SUM((J$1*$J8),(K$1*$K8),(L$1*$L8)*(M$1*$M8),(N$1*$N8),(O$1*$O8))*100 -> 320
A9: PH Link Initiation (ABCAP) | B9: Not Required | D9: 111114 | E9: OCR | F9: Daily | G9: 10 | H9: ABCAP SOP - Initiating Prospective Hire Link(2) | I9: Y | J9: 2 | K9: 4 | L9: 3 | M9: 5 | N9: 3 | O9: 5 | P9: =SUM((J$1*$J9),(K$1*$K9),(L$1*$L9)*(M$1*$M9),(N$1*$N9),(O$1*$O9))*100 -> 305
A10: Exit_Approval reassignment for Clearance | B10: Not Required | D10: 1931 | E10: NON-OCR | F10: Monthly | G10: 10 | H10: Exit Module SOP_V.5 | I10: Y | J10: 3 | K10: 5 | L10: 1 | M10: 2 | N10: 1 | O10: 4 | P10: =SUM((J$1*$J10),(K$1*$K10),(L$1*$L10)*(M$1*$M10),(N$1*$N10),(O$1*$O10))*100 -> 282 | Q10: Kunal
A11: Onboarding Initiation | B11: Part of EJF | C11: xxxx | D11: 2676 | E11: NON-OCR | F11: Weekly | G11: 10 | H11: Alt Onboarding L5 V.2 | I11: Y | J11: 3 | K11: 4 | L11: 2 | M11: 3 | N11: 2 | O11: 4 | P11: =SUM((J$1*$J11),(K$1*$K11),(L$1*$L11)*(M$1*$M11),(N$1*$N11),(O$1*$O11))*100 -> 276 | Q11: Kunal
A12: Poornata ID Creation (Add a Person) (Proposed Process Change) | C12: 2 | D12: 8925 | E12: OCR | F12: Daily | G12: 25 | I12: N | J12: 2 | K12: 4 | L12: 5 | M12: 4 | N12: 1 | O12: 4 | P12: =SUM((J$1*$J12),(K$1*$K12),(L$1*$L12)*(M$1*$M12),(N$1*$N12),(O$1*$O12))*100 -> 265 | Q12: Kunal
A13: Poornata ID creation (Through External Hire) – QC action and update if missing data-Proposed process change | C13: 2 | D13: 5854 | E13: OCR | F13: Daily | G13: 25 | I13: N | J13: 2 | K13: 4 | L13: 5 | M13: 3 | N13: 1 | O13: 4 | P13: =SUM((J$1*$J13),(K$1*$K13),(L$1*$L13)*(M$1*$M13),(N$1*$N13),(O$1*$O13))*100 -> 260 | Q13: Asawari
A14: Job Data Update (Excel Input / Bulk Data Update) | C14: 9 | D14: 45835 | E14: NON-OCR | F14: Daily | G14: 10 | I14: N | J14: 4 | K14: 1 | L14: 5 | M14: 5 | N14: 1 | O14: 3 | P14: =SUM((J$1*$J14),(K$1*$K14),(L$1*$L14)*(M$1*$M14),(N$1*$N14),(O$1*$O14))*100 -> 230 | Q14: Abhishek
A15: Data Change – Data Change | B15: Need at later stage | C15: xxxx | D15: 6804 | E15: NON-OCR | F15: Daily | G15: 10 | I15: N | J15: 3 | K15: 3 | L15: 5 | M15: 3 | N15: 1 | O15: 3 | P15: =SUM((J$1*$J15),(K$1*$K15),(L$1*$L15)*(M$1*$M15),(N$1*$N15),(O$1*$O15))*100 -> 230 | Q15: Abhishek
A16: JD linkage | B16: Not Required | D16: 4037 | E16: NON-OCR | F16: Daily | G16: 10 | H16: JD Update SOP | I16: Y | J16: 1 | K16: 3 | L16: 5 | M16: 3 | N16: 1 | O16: 4 | P16: =SUM((J$1*$J16),(K$1*$K16),(L$1*$L16)*(M$1*$M16),(N$1*$N16),(O$1*$O16))*100 -> 225
A17: Job Data Update (Resignation, Separation and Transfer) | B17: Duplicate | D17: 4381 | E17: NON-OCR | F17: On Demand | G17: 10 | H17: JD Update SOP | I17: Y | J17: 1 | K17: 3 | L17: 5 | M17: 3 | N17: 1 | O17: 4 | P17: =SUM((J$1*$J17),(K$1*$K17),(L$1*$L17)*(M$1*$M17),(N$1*$N17),(O$1*$O17))*100 -> 225 | Q17: Poonam
A18: Mobility_HR Initiated Transfer | B18: Duplicate | D18: 7125 | E18: OCR | F18: Monthly | G18: 10 | H18: Mobility SOP | I18: Y | J18: 1 | K18: 5 | L18: 1 | M18: 4 | N18: 3 | O18: 3 | P18: =SUM((J$1*$J18),(K$1*$K18),(L$1*$L18)*(M$1*$M18),(N$1*$N18),(O$1*$O18))*100 -> 219 | Q18: Kunal
A19: Transfer of performance document | B19: Check script option | C19: 8 | D19: 3558 | J19: 2 | K19: 5 | L19: 5 | M19: 3 | N19: 1 | O19: 2 | P19: =SUM((J$1*$J19),(K$1*$K19),(L$1*$L19)*(M$1*$M19),(N$1*$N19),(O$1*$O19))*100 -> 205 | Q19: Asawari
A20: Creation of performance document | B20: Exception Management | D20: 2013 | E20: NON-OCR | F20: Annual | G20: 10 | H20: SOP_Creation of Performance Document | I20: Y | J20: 4 | K20: 5 | L20: 5 | M20: 2 | N20: 5 | P20: =SUM((J$1*$J20),(K$1*$K20),(L$1*$L20)*(M$1*$M20),(N$1*$N20),(O$1*$O20))*100 -> 190 | Q20: Asawari
A21: Job Description Update | C21: 0 | D21: 7168 | E21: NON-OCR | F21: Daily | G21: 10 | H21: JD Update SOP | I21: Y | J21: 2 | K21: 4 | L21: 4 | M21: 3 | N21: 1 | O21: 1 | P21: =SUM((J$1*$J21),(K$1*$K21),(L$1*$L21)*(M$1*$M21),(N$1*$N21),(O$1*$O21))*100 -> 152 | Q21: Asawari
A22: Holiday Schedule upload | C22: 7 | D22: 10287 | E22: NON-OCR | F22: Monthly | G22: 10 | H22: Holiday Calender Upload SOP | I22: Y | J22: 1 | K22: 5 | L22: 5 | M22: 1 | N22: 1 | O22: 1 | P22: =SUM((J$1*$J22),(K$1*$K22),(L$1*$L22)*(M$1*$M22),(N$1*$N22),(O$1*$O22))*100 -> 140 | Q22: Kunal
A23: Cancelling of performance document | B23: Already backend script available | D23: 1639 | E23: NON-OCR | F23: Annual | G23: 10 | H23: SOP_Cancellation of Performance Document | I23: Y | J23: 3 | K23: 3 | L23: 5 | M23: 2 | N23: 5 | P23: =SUM((J$1*$J23),(K$1*$K23),(L$1*$L23)*(M$1*$M23),(N$1*$N23),(O$1*$O23))*100 -> 140 | Q23: Kunal
A24: Leave Balance upload | B24: Not Required | D24: 4243 | E24: NON-OCR | F24: Monthly | G24: 12 | H24: Leave Balance Upload SOP_V3 | I24: Y | J24: 1 | K24: 5 | L24: 5 | M24: 4 | N24: 5 | P24: =SUM((J$1*$J24),(K$1*$K24),(L$1*$L24)*(M$1*$M24),(N$1*$N24),(O$1*$O24))*100 -> 140 | Q24: Kunal
A25: Bank Data Update | C25: 5 | D25: 3695 | E25: OCR | F25: Weekly | G25: 8 | H25: WFA Global SOP | I25: Y | J25: 1 | K25: 4 | L25: 5 | M25: 2 | N25: 1 | O25: 1 | P25: =SUM((J$1*$J25),(K$1*$K25),(L$1*$L25)*(M$1*$M25),(N$1*$N25),(O$1*$O25))*100 -> 130 | Q25: Abhishek
A26: Creation and Assigning of Curriculum/ Deeplinks/ Online Courses/ Uploading Videos | B26: Learning | C26: TBD | D26: 2025 | E26: NON-OCR | F26: Monthly | G26: 10 | H26: SOP_CSOD_Creation & Assign Curriculum SOP_CSOD_Upload and Assign Online course_V1 SOP_CSOD_Upload and Assign Video_V1 | I26: Y | J26: 1 | K26: 5 | L26: 5 | M26: 2 | N26: 5 | P26: =SUM((J$1*$J26),(K$1*$K26),(L$1*$L26)*(M$1*$M26),(N$1*$N26),(O$1*$O26))*100 -> 130 | Q26: Abhishek
A27: New/ Old Event | B27: Learning | C27: TBD | D27: 2192 | E27: NON-OCR | F27: Daily | G27: 10 | H27: Creating Event, Session & Adding Trainer - Group Creation SOP | I27: Y | J27: 2 | K27: 3 | L27: 1 | M27: 2 | N27: 1 | O27: 1 | P27: =SUM((J$1*$J27),(K$1*$K27),(L$1*$L27)*(M$1*$M27),(N$1*$N27),(O$1*$O27))*100 -> 127 | Q27: Abhishek
A28: Creation of Potential Assessment Document | B28: Already there - Not required | D28: 5337 | E28: NON-OCR | F28: Daily | G28: 5 | H28: SOP_Potential Management_Creation of Potential Assessment Document | I28: Y | J28: 2 | K28: 2 | L28: 1 | M28: 1 | N28: 1 | O28: 1 | P28: =SUM((J$1*$J28),(K$1*$K28),(L$1*$L28)*(M$1*$M28),(N$1*$N28),(O$1*$O28))*100 -> 111 | Q28: Abhishek
A29: Position Creation/ Updation/ Deactivation and JD Linkage (Job Arch) | B29: Already in Production | C29: 0 | D29: 9247 | E29: NON-OCR | F29: Daily | G29: 10 | I29: N | P29: =SUM((J$1*$J29),(K$1*$K29),(L$1*$L29)*(M$1*$M29),(N$1*$N29),(O$1*$O29))*100 -> 0 | Q29: Poonam
